Workbook
Name city: Data_Preprocessing!$R$2:$R$1048576
Name Close_Match_Flag: Data_Preprocessing!$X$2:$X$1048576
Name Correct_Winner: Data_Preprocessing!$P$2:$P$1048576
Name date: Data_Preprocessing!$E$2:$E$1048576
Name High_Scoring_Flag: Data_Preprocessing!$Z$2:$Z$1048576
Name match_no: Data_Preprocessing!$C$2:$C$1048576
Name Match_Type: Data_Preprocessing!$D$2:$D$1048576
Name player_of_match: Data_Preprocessing!$L$2:$L$1048576
Name result: Data_Preprocessing!$U$2:$U$1048576
Name season: Data_Preprocessing!$A$2:$A$1048576
Name Slicer_Match_Type: #N/A
Name Slicer_season: #N/A
Name Slicer_Team_Name: #N/A
Name Slicer_venue: #N/A
Name Team: Data_Preprocessing!$AC$2:$AC$1048576
Name team_1: Data_Preprocessing!$F$2:$F$1048576
Name team_1_score: Data_Preprocessing!$G$2:$G$1048576
Name team_1_wicket: Data_Preprocessing!$H$2:$H$1048576
Name team_2: Data_Preprocessing!$I$2:$I$1048576
Name team_2_score: Data_Preprocessing!$J$2:$J$1048576
Name team_2_wicket: Data_Preprocessing!$K$2:$K$1048576
Name Team_Name: Data_Preprocessing!$AD$2:$AD$1048576
Name toss_decision: Data_Preprocessing!$N$2:$N$1048576
Name toss_winner: Data_Preprocessing!$M$2:$M$1048576
Name Total_Runs: Data_Preprocessing!$Y$2:$Y$1048576
Name umpire_1: Data_Preprocessing!$AA$2:$AA$1048576
Name umpire_2: Data_Preprocessing!$AB$2:$AB$1048576
Name venue: Data_Preprocessing!$Q$2:$Q$1048576
Name win_by_runs: Data_Preprocessing!$T$2:$T$1048576
Name Win_By_Type: Data_Preprocessing!$V$2:$V$1048576
Name win_by_wickets: Data_Preprocessing!$S$2:$S$1048576
Name Win_Flag: Data_Preprocessing!$AE$2:$AE$1048576
Name Win_Margin: Data_Preprocessing!$W$2:$W$1048576
Name winner: Data_Preprocessing!$O$2:$O$1048576
Name Year: Data_Preprocessing!$B$2:$B$1048576

Sheet Raw_Data
A1: season | B1: match_no | C1: date | D1: team_1 | E1: team_1_score | F1: team_1_wicket | G1: team_2 | H1: team_2_score | I1: team_2_wicket | J1: player_of_match | K1: toss_winner | L1: toss_decision | M1: winner | N1: venue | O1: city | P1: win_by_wickets | Q1: win_by_runs | R1: result | S1: umpire_1 | T1: umpire_2
A2: 2011/12 | B2: Final | C2: Feb 29 2012 | D2: Barisal Burners | E2: 140 | F2: 7 | G2: Dhaka Gladiators | H2: 144 | I2: 2 | J2: Imran Nazir | K2: Dhaka Gladiators | L2: field first | M2: Dhaka | N2: SBNCS | O2: Mirpur | P2: 8 | Q2: 0 | R2: 8 wickets | S2: David Orchard | T2: Enamul Haque
A3: 2011/12 | B3: 2nd | C3: Feb 28 2012 | D3: Dhaka Gladiators | E3: 191 | F3: 4 | G3: Khulna Royal Bengals | H3: 182 | I3: 7 | J3: Azhar Mahmood | K3: Dhaka Gladiators | L3: bat first | M3: Dhaka | N3: SBNCS | O3: Mirpur | P3: 0 | Q3: 9 | R3: 9 runs | S3: Enamul Haque | T3: Nadir Shah
A4: 2011/12 | B4: 1st | C4: Feb 28 2012 | D4: Duronto Rajshahi | E4: 184 | F4: 6 | G4: Barisal Burners | H4: 189 | I4: 2 | J4: Ahmed Shehzad | K4: Barisal Burners | L4: field first | M4: Barisal | N4: SBNCS | O4: Mirpur | P4: 8 | Q4: 0 | R4: 8 wickets | S4: David Orchard | T4: Sharfuddoula
A5: 2011/12 | B5: 29th | C5: Feb 27 2012 | D5: Dhaka Gladiators | E5: 116 | F5: 10 | G5: Duronto Rajshahi | H5: 120 | I5: 7 | J5: Mohammad Sami | K5: Dhaka Gladiators | L5: bat first | M5: Rajshahi | N5: SBNCS | O5: Mirpur | P5: 3 | Q5: 0 | R5: 3 wickets | S5: Mahfuzur Rahman | T5: Nadir Shah
A6: 2011/12 | B6: 28th | C6: Feb 26 2012 | D6: Chittagong Kings | E6: 150 | F6: 9 | G6: Barisal Burners | H6: 151 | I6: 5 | J6: Brad Hodge | K6: Barisal Burners | L6: field first | M6: Barisal | N6: SBNCS | O6: Mirpur | P6: 5 | Q6: 0 | R6: 5 wickets | S6: Gazi Sohel | T6: Jeremy Lloyds
A7: 2011/12 | B7: 27th | C7: Feb 26 2012 | D7: Khulna Royal Bengals | E7: 106 | F7: 10 | G7: Duronto Rajshahi | H7: 110 | I7: 2 | J7: Sean Ervine | K7: Khulna Royal Bengals | L7: bat first | M7: Rajshahi | N7: SBNCS | O7: Mirpur | P7: 8 | Q7: 0 | R7: 8 wickets | S7: David Orchard | T7: Nadir Shah
A8: 2011/12 | B8: 26th | C8: Feb 25 2012 | D8: Sylhet Royals | E8: 165 | F8: 3 | G8: Chittagong Kings | H8: 130 | I8: 8 | J8: Peter Trego | K8: Chittagong Kings | L8: field first | M8: Royals | N8: SBNCS | O8: Mirpur | P8: 0 | Q8: 35 | R8: 35 runs | S8: David Orchard | T8: Masudur Rahman
A9: 2011/12 | B9: 25th | C9: Feb 25 2012 | D9: Barisal Burners | E9: 156 | F9: 6 | G9: Dhaka Gladiators | H9: 160 | I9: 5 | J9: Imran Nazir | K9: Dhaka Gladiators | L9: field first | M9: Dhaka | N9: SBNCS | O9: Mirpur | P9: 5 | Q9: 0 | R9: 5 wickets | S9: Jeremy Lloyds | T9: Nadir Shah
A10: 2011/12 | B10: 24th | C10: Feb 24 2012 | D10: Duronto Rajshahi | E10: 124 | F10: 9 | G10: Sylhet Royals | H10: 125 | I10: 1 | J10: Sohail Tanvir | K10: Sylhet Royals | L10: field first | M10: Royals | N10: SBNCS | O10: Mirpur | P10: 9 | Q10: 0 | R10: 9 wickets | S10: Anisur Rahman | T10: Jeremy Lloyds
A11: 2012/13 | B11: Final | C11: Feb 19 2013 | D11: Dhaka Gladiators | E11: 172 | F11: 9 | G11: Chittagong Kings | H11: 129 | I11: 10 | J11: Mosharraf Hossain | K11: Chittagong Kings | L11: field first | M11: Dhaka | N11: SBNCS | O11: Mirpur | P11: 0 | Q11: 43 | R11: 43 runs | S11: Enamul Haque | T11: Richard Illingworth
A12: 2011/12 | B12: 23rd | C12: Feb 24 2012 | D12: Chittagong Kings | E12: 120 | F12: 6 | G12: Dhaka Gladiators | H12: 107 | I12: 9 | J12: Dwayne Bravo | K12: Dhaka Gladiators | L12: field first | M12: Chittagong | N12: SBNCS | O12: Mirpur | P12: 0 | Q12: 13 | R12: 13 runs | S12: David Orchard | T12: Nadir Shah
A13: 2012/13 | B13: Semi-Final | C13: Feb 18 2013 | D13: Sylhet Royals | E13: 149 | F13: 7 | G13: Chittagong Kings | H13: 150 | I13: 7 | J13: Ryan ten Doeschate | K13: Chittagong Kings | L13: field first | M13: Chittagong | N13: SBNCS | O13: Mirpur | P13: 3 | Q13: 0 | R13: 3 wickets | S13: Enamul Haque | T13: Jeremy Lloyds
... A482: 2024/25 | B482: Final | C482: Feb 7 2025 | D482: Chittagong Kings | E482: 194 | F482: 7 | G482: Fortune Barishal | H482: 195 | I482: 7 | J482: Tamim Iqbal | K482: Fortune Barishal | L482: field first | M482: Fortune Barishal | N482: SBNCS | O482: Mirpur | P482: 0 | Q482: 3 | R482: 3 wickets | S482: Gazi Sohel | T482: Masudur Rahman

Sheet Clean_Data
A1: season | B1: Year | C1: match_no | D1: Match_Type | E1: date | F1: team_1 | G1: team_1_score | H1: team_1_wicket | I1: team_2 | J1: team_2_score | K1: team_2_wicket | L1: player_of_match | M1: toss_winner | N1: toss_decision | O1: winner | P1: Correct_Winner | Q1: venue | R1: city | S1: win_by_wickets | T1: win_by_runs | U1: result | V1: Win_By_Type | W1: Win_Margin | X1: Close_Match_Flag | Y1: Total_Runs | Z1: High_Scoring_Flag | AA1: umpire_1 | AB1: umpire_2
A2: 2011/12 | B2: =LEFT(Clean_Data!$A2,4) -> 2011 | C2: Final | D2: =IF(ISNUMBER(SEARCH("Final",Clean_Data!$C2)),"Final", IF(ISNUMBER(SEARCH("Semi",Clean_Data!$C2)),"Semi-Final", IF(ISNUMBER(SEARCH("Elimination",Clean_Data!$C2)),"Eliminator", "League"))) -> Final | E2: Feb 29 2012 | F2: Barisal Burners | G2: 140 | H2: 7 | I2: Dhaka Gladiators | J2: 144 | K2: 2 | L2: Imran Nazir | M2: Dhaka Gladiators | N2: field first | O2: Dhaka | P2: =IF(Clean_Data!$G2>Clean_Data!$J2,Clean_Data!$F2,Clean_Data!$I2) -> Dhaka Gladiators | Q2: SBNCS | R2: Mirpur | S2: 8 | T2: 0 | U2: 8 wickets | V2: =IF(Clean_Data!$T2>0,"Runs","Wickets") -> Wickets | W2: =IF(Clean_Data!$T2>0,Clean_Data!$T2,Clean_Data!$S2) -> 8 | X2: =IF(Clean_Data!$W2<=10,"Close Match","Normal") -> Close Match | Y2: =Clean_Data!$G2+Clean_Data!$J2 -> 284 | Z2: =IF(Clean_Data!$Y2>=170,"170+ Match","Below 170") -> 170+ Match | AA2: David Orchard | AB2: Enamul Haque
A3: 2011/12 | B3: =LEFT(Clean_Data!$A3,4) -> 2011 | C3: 2nd | D3: =IF(ISNUMBER(SEARCH("Final",Clean_Data!$C3)),"Final", IF(ISNUMBER(SEARCH("Semi",Clean_Data!$C3)),"Semi-Final", IF(ISNUMBER(SEARCH("Elimination",Clean_Data!$C3)),"Eliminator", "League"))) -> League | E3: Feb 28 2012 | F3: Dhaka Gladiators | G3: 191 | H3: 4 | I3: Khulna Royal Bengals | J3: 182 | K3: 7 | L3: Azhar Mahmood | M3: Dhaka Gladiators | N3: bat first | O3: Dhaka | P3: =IF(Clean_Data!$G3>Clean_Data!$J3,Clean_Data!$F3,Clean_Data!$I3) -> Dhaka Gladiators | Q3: SBNCS | R3: Mirpur | S3: 0 | T3: 9 | U3: 9 runs | V3: =IF(Clean_Data!$T3>0,"Runs","Wickets") -> Runs | W3: =IF(Clean_Data!$T3>0,Clean_Data!$T3,Clean_Data!$S3) -> 9 | X3: =IF(Clean_Data!$W3<=10,"Close Match","Normal") -> Close Match | Y3: =Clean_Data!$G3+Clean_Data!$J3 -> 373 | Z3: =IF(Clean_Data!$Y3>=170,"170+ Match","Below 170") -> 170+ Match | AA3: Enamul Haque | AB3: Nadir Shah
A4: 2011/12 | B4: =LEFT(Clean_Data!$A4,4) -> 2011 | C4: 1st | D4: =IF(ISNUMBER(SEARCH("Final",Clean_Data!$C4)),"Final", IF(ISNUMBER(SEARCH("Semi",Clean_Data!$C4)),"Semi-Final", IF(ISNUMBER(SEARCH("Elimination",Clean_Data!$C4)),"Eliminator", "League"))) -> League | E4: Feb 28 2012 | F4: Duronto Rajshahi | G4: 184 | H4: 6 | I4: Barisal Burners | J4: 189 | K4: 2 | L4: Ahmed Shehzad | M4: Barisal Burners | N4: field first | O4: Barisal | P4: =IF(Clean_Data!$G4>Clean_Data!$J4,Clean_Data!$F4,Clean_Data!$I4) -> Barisal Burners | Q4: SBNCS | R4: Mirpur | S4: 8 | T4: 0 | U4: 8 wickets | V4: =IF(Clean_Data!$T4>0,"Runs","Wickets") -> Wickets | W4: =IF(Clean_Data!$T4>0,Clean_Data!$T4,Clean_Data!$S4) -> 8 | X4: =IF(Clean_Data!$W4<=10,"Close Match","Normal") -> Close Match | Y4: =Clean_Data!$G4+Clean_Data!$J4 -> 373 | Z4: =IF(Clean_Data!$Y4>=170,"170+ Match","Below 170") -> 170+ Match | AA4: David Orchard | AB4: Sharfuddoula
A5: 2011/12 | B5: =LEFT(Clean_Data!$A5,4) -> 2011 | C5: 29th | D5: =IF(ISNUMBER(SEARCH("Final",Clean_Data!$C5)),"Final", IF(ISNUMBER(SEARCH("Semi",Clean_Data!$C5)),"Semi-Final", IF(ISNUMBER(SEARCH("Elimination",Clean_Data!$C5)),"Eliminator", "League"))) -> League | E5: Feb 27 2012 | F5: Dhaka Gladiators | G5: 116 | H5: 10 | I5: Duronto Rajshahi | J5: 120 | K5: 7 | L5: Mohammad Sami | M5: Dhaka Gladiators | N5: bat first | O5: Rajshahi | P5: =IF(Clean_Data!$G5>Clean_Data!$J5,Clean_Data!$F5,Clean_Data!$I5) -> Duronto Rajshahi | Q5: SBNCS | R5: Mirpur | S5: 3 | T5: 0 | U5: 3 wickets | V5: =IF(Clean_Data!$T5>0,"Runs","Wickets") -> Wickets | W5: =IF(Clean_Data!$T5>0,Clean_Data!$T5,Clean_Data!$S5) -> 3 | X5: =IF(Clean_Data!$W5<=10,"Close Match","Normal") -> Close Match | Y5: =Clean_Data!$G5+Clean_Data!$J5 -> 236 | Z5: =IF(Clean_Data!$Y5>=170,"170+ Match","Below 170") -> 170+ Match | AA5: Mahfuzur Rahman | AB5: Nadir Shah
A6: 2011/12 | B6: =LEFT(Clean_Data!$A6,4) -> 2011 | C6: 28th | D6: =IF(ISNUMBER(SEARCH("Final",Clean_Data!$C6)),"Final", IF(ISNUMBER(SEARCH("Semi",Clean_Data!$C6)),"Semi-Final", IF(ISNUMBER(SEARCH("Elimination",Clean_Data!$C6)),"Eliminator", "League"))) -> League | E6: Feb 26 2012 | F6: Chittagong Kings | G6: 150 | H6: 9 | I6: Barisal Burners | J6: 151 | K6: 5 | L6: Brad Hodge | M6: Barisal Burners | N6: field first | O6: Barisal | P6: =IF(Clean_Data!$G6>Clean_Data!$J6,Clean_Data!$F6,Clean_Data!$I6) -> Barisal Burners | Q6: SBNCS | R6: Mirpur | S6: 5 | T6: 0 | U6: 5 wickets | V6: =IF(Clean_Data!$T6>0,"Runs","Wickets") -> Wickets | W6: =IF(Clean_Data!$T6>0,Clean_Data!$T6,Clean_Data!$S6) -> 5 | X6: =IF(Clean_Data!$W6<=10,"Close Match","Normal") -> Close Match | Y6: =Clean_Data!$G6+Clean_Data!$J6 -> 301 | Z6: =IF(Clean_Data!$Y6>=170,"170+ Match","Below 170") -> 170+ Match | AA6: Gazi Sohel | AB6: Jeremy Lloyds
A7: 2011/12 | B7: =LEFT(Clean_Data!$A7,4) -> 2011 | C7: 27th | D7: =IF(ISNUMBER(SEARCH("Final",Clean_Data!$C7)),"Final", IF(ISNUMBER(SEARCH("Semi",Clean_Data!$C7)),"Semi-Final", IF(ISNUMBER(SEARCH("Elimination",Clean_Data!$C7)),"Eliminator", "League"))) -> League | E7: Feb 26 2012 | F7: Khulna Royal Bengals | G7: 106 | H7: 10 | I7: Duronto Rajshahi | J7: 110 | K7: 2 | L7: Sean Ervine | M7: Khulna Royal Bengals | N7: bat first | O7: Rajshahi | P7: =IF(Clean_Data!$G7>Clean_Data!$J7,Clean_Data!$F7,Clean_Data!$I7) -> Duronto Rajshahi | Q7: SBNCS | R7: Mirpur | S7: 8 | T7: 0 | U7: 8 wickets | V7: =IF(Clean_Data!$T7>0,"Runs","Wickets") -> Wickets | W7: =IF(Clean_Data!$T7>0,Clean_Data!$T7,Clean_Data!$S7) -> 8 | X7: =IF(Clean_Data!$W7<=10,"Close Match","Normal") -> Close Match | Y7: =Clean_Data!$G7+Clean_Data!$J7 -> 216 | Z7: =IF(Clean_Data!$Y7>=170,"170+ Match","Below 170") -> 170+ Match | AA7: David Orchard | AB7: Nadir Shah
A8: 2011/12 | B8: =LEFT(Clean_Data!$A8,4) -> 2011 | C8: 26th | D8: =IF(ISNUMBER(SEARCH("Final",Clean_Data!$C8)),"Final", IF(ISNUMBER(SEARCH("Semi",Clean_Data!$C8)),"Semi-Final", IF(ISNUMBER(SEARCH("Elimination",Clean_Data!$C8)),"Eliminator", "League"))) -> League | E8: Feb 25 2012 | F8: Sylhet Royals | G8: 165 | H8: 3 | I8: Chittagong Kings | J8: 130 | K8: 8 | L8: Peter Trego | M8: Chittagong Kings | N8: field first | O8: Royals | P8: =IF(Clean_Data!$G8>Clean_Data!$J8,Clean_Data!$F8,Clean_Data!$I8) -> Sylhet Royals | Q8: SBNCS | R8: Mirpur | S8: 0 | T8: 35 | U8: 35 runs | V8: =IF(Clean_Data!$T8>0,"Runs","Wickets") -> Runs | W8: =IF(Clean_Data!$T8>0,Clean_Data!$T8,Clean_Data!$S8) -> 35 | X8: =IF(Clean_Data!$W8<=10,"Close Match","Normal") -> Normal | Y8: =Clean_Data!$G8+Clean_Data!$J8 -> 295 | Z8: =IF(Clean_Data!$Y8>=170,"170+ Match","Below 170") -> 170+ Match | AA8: David Orchard | AB8: Masudur Rahman
A9: 2011/12 | B9: =LEFT(Clean_Data!$A9,4) -> 2011 | C9: 25th | D9: =IF(ISNUMBER(SEARCH("Final",Clean_Data!$C9)),"Final", IF(ISNUMBER(SEARCH("Semi",Clean_Data!$C9)),"Semi-Final", IF(ISNUMBER(SEARCH("Elimination",Clean_Data!$C9)),"Eliminator", "League"))) -> League | E9: Feb 25 2012 | F9: Barisal Burners | G9: 156 | H9: 6 | I9: Dhaka Gladiators | J9: 160 | K9: 5 | L9: Imran Nazir | M9: Dhaka Gladiators | N9: field first | O9: Dhaka | P9: =IF(Clean_Data!$G9>Clean_Data!$J9,Clean_Data!$F9,Clean_Data!$I9) -> Dhaka Gladiators | Q9: SBNCS | R9: Mirpur | S9: 5 | T9: 0 | U9: 5 wickets | V9: =IF(Clean_Data!$T9>0,"Runs","Wickets") -> Wickets | W9: =IF(Clean_Data!$T9>0,Clean_Data!$T9,Clean_Data!$S9) -> 5 | X9: =IF(Clean_Data!$W9<=10,"Close Match","Normal") -> Close Match | Y9: =Clean_Data!$G9+Clean_Data!$J9 -> 316 | Z9: =IF(Clean_Data!$Y9>=170,"170+ Match","Below 170") -> 170+ Match | AA9: Jeremy Lloyds | AB9: Nadir Shah
A10: 2011/12 | B10: =LEFT(Clean_Data!$A10,4) -> 2011 | C10: 24th | D10: =IF(ISNUMBER(SEARCH("Final",Clean_Data!$C10)),"Final", IF(ISNUMBER(SEARCH("Semi",Clean_Data!$C10)),"Semi-Final", IF(ISNUMBER(SEARCH("Elimination",Clean_Data!$C10)),"Eliminator", "League"))) -> League | E10: Feb 24 2012 | F10: Duronto Rajshahi | G10: 124 | H10: 9 | I10: Sylhet Royals | J10: 125 | K10: 1 | L10: Sohail Tanvir | M10: Sylhet Royals | N10: field first | O10: Royals | P10: =IF(Clean_Data!$G10>Clean_Data!$J10,Clean_Data!$F10,Clean_Data!$I10) -> Sylhet Royals | Q10: SBNCS | R10: Mirpur | S10: 9 | T10: 0 | U10: 9 wickets | V10: =IF(Clean_Data!$T10>0,"Runs","Wickets") -> Wickets | W10: =IF(Clean_Data!$T10>0,Clean_Data!$T10,Clean_Data!$S10) -> 9 | X10: =IF(Clean_Data!$W10<=10,"Close Match","Normal") -> Close Match | Y10: =Clean_Data!$G10+Clean_Data!$J10 -> 249 | Z10: =IF(Clean_Data!$Y10>=170,"170+ Match","Below 170") -> 170+ Match | AA10: Anisur Rahman | AB10: Jeremy Lloyds
A11: 2012/13 | B11: =LEFT(Clean_Data!$A11,4) -> 2012 | C11: Final | D11: =IF(ISNUMBER(SEARCH("Final",Clean_Data!$C11)),"Final", IF(ISNUMBER(SEARCH("Semi",Clean_Data!$C11)),"Semi-Final", IF(ISNUMBER(SEARCH("Elimination",Clean_Data!$C11)),"Eliminator", "League"))) -> Final | E11: Feb 19 2013 | F11: Dhaka Gladiators | G11: 172 | H11: 9 | I11: Chittagong Kings | J11: 129 | K11: 10 | L11: Mosharraf Hossain | M11: Chittagong Kings | N11: field first | O11: Dhaka | P11: =IF(Clean_Data!$G11>Clean_Data!$J11,Clean_Data!$F11,Clean_Data!$I11) -> Dhaka Gladiators | Q11: SBNCS | R11: Mirpur | S11: 0 | T11: 43 | U11: 43 runs | V11: =IF(Clean_Data!$T11>0,"Runs","Wickets") -> Runs | W11: =IF(Clean_Data!$T11>0,Clean_Data!$T11,Clean_Data!$S11) -> 43 | X11: =IF(Clean_Data!$W11<=10,"Close Match","Normal") -> Normal | Y11: =Clean_Data!$G11+Clean_Data!$J11 -> 301 | Z11: =IF(Clean_Data!$Y11>=170,"170+ Match","Below 170") -> 170+ Match | AA11: Enamul Haque | AB11: Richard Illingworth
A12: 2011/12 | B12: =LEFT(Clean_Data!$A12,4) -> 2011 | C12: 23rd | D12: =IF(ISNUMBER(SEARCH("Final",Clean_Data!$C12)),"Final", IF(ISNUMBER(SEARCH("Semi",Clean_Data!$C12)),"Semi-Final", IF(ISNUMBER(SEARCH("Elimination",Clean_Data!$C12)),"Eliminator", "League"))) -> League | E12: Feb 24 2012 | F12: Chittagong Kings | G12: 120 | H12: 6 | I12: Dhaka Gladiators | J12: 107 | K12: 9 | L12: Dwayne Bravo | M12: Dhaka Gladiators | N12: field first | O12: Chittagong | P12: =IF(Clean_Data!$G12>Clean_Data!$J12,Clean_Data!$F12,Clean_Data!$I12) -> Chittagong Kings | Q12: SBNCS | R12: Mirpur | S12: 0 | T12: 13 | U12: 13 runs | V12: =IF(Clean_Data!$T12>0,"Runs","Wickets") -> Runs | W12: =IF(Clean_Data!$T12>0,Clean_Data!$T12,Clean_Data!$S12) -> 13 | X12: =IF(Clean_Data!$W12<=10,"Close Match","Normal") -> Normal | Y12: =Clean_Data!$G12+Clean_Data!$J12 -> 227 | Z12: =IF(Clean_Data!$Y12>=170,"170+ Match","Below 170") -> 170+ Match | AA12: David Orchard | AB12: Nadir Shah
A13: 2012/13 | B13: =LEFT(Clean_Data!$A13,4) -> 2012 | C13: Semi-Final | D13: =IF(ISNUMBER(SEARCH("Final",Clean_Data!$C13)),"Final", IF(ISNUMBER(SEARCH("Semi",Clean_Data!$C13)),"Semi-Final", IF(ISNUMBER(SEARCH("Elimination",Clean_Data!$C13)),"Eliminator", "League"))) -> Final | E13: Feb 18 2013 | F13: Sylhet Royals | G13: 149 | H13: 7 | I13: Chittagong Kings | J13: 150 | K13: 7 | L13: Ryan ten Doeschate | M13: Chittagong Kings | N13: field first | O13: Chittagong | P13: =IF(Clean_Data!$G13>Clean_Data!$J13,Clean_Data!$F13,Clean_Data!$I13) -> Chittagong Kings | Q13: SBNCS | R13: Mirpur | S13: 3 | T13: 0 | U13: 3 wickets | V13: =IF(Clean_Data!$T13>0,"Runs","Wickets") -> Wickets | W13: =IF(Clean_Data!$T13>0,Clean_Data!$T13,Clean_Data!$S13) -> 3 | X13: =IF(Clean_Data!$W13<=10,"Close Match","Normal") -> Close Match | Y13: =Clean_Data!$G13+Clean_Data!$J13 -> 299 | Z13: =IF(Clean_Data!$Y13>=170,"170+ Match","Below 170") -> 170+ Match | AA13: Enamul Haque | AB13: Jeremy Lloyds
... A482: 2024/25 | B482: =LEFT(Clean_Data!$A482,4) -> 2024 | C482: Final | D482: =IF(ISNUMBER(SEARCH("Final",Clean_Data!$C482)),"Final", IF(ISNUMBER(SEARCH("Semi",Clean_Data!$C482)),"Semi-Final", IF(ISNUMBER(SEARCH("Elimination",Clean_Data!$C482)),"Eliminator", "League"))) -> Final | E482: Feb 7 2025 | F482: Chittagong Kings | G482: 194 | H482: 7 | I482: Fortune Barishal | J482: 195 | K482: 7 | L482: Tamim Iqbal | M482: Fortune Barishal | N482: field first | O482: Fortune Barishal | P482: =IF(Clean_Data!$G482>Clean_Data!$J482,Clean_Data!$F482,Clean_Data!$I482) -> Fortune Barishal | Q482: SBNCS | R482: Mirpur | S482: 0 | T482: 3 | U482: 3 wickets | V482: =IF(Clean_Data!$T482>0,"Runs","Wickets") -> Runs | W482: =IF(Clean_Data!$T482>0,Clean_Data!$T482,Clean_Data!$S482) -> 3 | X482: =IF(Clean_Data!$W482<=10,"Close Match","Normal") -> Close Match | Y482: =Clean_Data!$G482+Clean_Data!$J482 -> 389 | Z482: =IF(Clean_Data!$Y482>=170,"170+ Match","Below 170") -> 170+ Match | AA482: Gazi Sohel | AB482: Masudur Rahman

Sheet Data_Preprocessing
A1: season | B1: Year | C1: match_no | D1: Match_Type | E1: date | F1: team_1 | G1: team_1_score | H1: team_1_wicket | I1: team_2 | J1: team_2_score | K1: team_2_wicket | L1: player_of_match | M1: toss_winner | N1: toss_decision | O1: winner | P1: Correct_Winner | Q1: venue | R1: city | S1: win_by_wickets | T1: win_by_runs | U1: result | V1: Win_By_Type | W1: Win_Margin | X1: Close_Match_Flag | Y1: Total_Runs | Z1: High_Scoring_Flag | AA1: umpire_1 | AB1: umpire_2 | AC1: Team | AD1: Team_Name | AE1: Win_Flag
A2: 2011/12 | B2: 2011 | C2: Final | D2: Final | E2: Feb 29 2012 | F2: Barisal Burners | G2: 140 | H2: 7 | I2: =Clean_Data!$I2 -> Dhaka Gladiators | J2: 144 | K2: 2 | L2: Imran Nazir | M2: Dhaka Gladiators | N2: field first | O2: Dhaka | P2: Dhaka Gladiators | Q2: SBNCS | R2: Mirpur | S2: 8 | T2: 0 | U2: 8 wickets | V2: Wickets | W2: 8 | X2: Close Match | Y2: 284 | Z2: 170+ Match | AA2: David Orchard | AB2: Enamul Haque | AC2: team_1 | AD2: Barisal Burners | AE2: =IF(Table5[[#This Row],[Team_Name]]=Table5[[#This Row],[Correct_Winner]],1,0) -> 0
A3: 2011/12 | B3: 2011 | C3: Final | D3: Final | E3: Feb 29 2012 | F3: Dhaka Gladiators | G3: 140 | H3: 7 | I3: =Clean_Data!$I3 -> Khulna Royal Bengals | J3: 144 | K3: 2 | L3: Imran Nazir | M3: Dhaka Gladiators | N3: field first | O3: Dhaka | P3: Dhaka Gladiators | Q3: SBNCS | R3: Mirpur | S3: 8 | T3: 0 | U3: 8 wickets | V3: Wickets | W3: 8 | X3: Close Match | Y3: 284 | Z3: 170+ Match | AA3: David Orchard | AB3: Enamul Haque | AC3: team_2 | AD3: Dhaka Gladiators | AE3: =IF(Table5[[#This Row],[Team_Name]]=Table5[[#This Row],[Correct_Winner]],1,0) -> 1
A4: 2011/12 | B4: 2011 | C4: 2nd | D4: League | E4: Feb 28 2012 | F4: Duronto Rajshahi | G4: 191 | H4: 4 | I4: =Clean_Data!$I4 -> Barisal Burners | J4: 182 | K4: 7 | L4: Azhar Mahmood | M4: Dhaka Gladiators | N4: bat first | O4: Dhaka | P4: Dhaka Gladiators | Q4: SBNCS | R4: Mirpur | S4: 0 | T4: 9 | U4: 9 runs | V4: Runs | W4: 9 | X4: Close Match | Y4: 373 | Z4: 170+ Match | AA4: Enamul Haque | AB4: Nadir Shah | AC4: team_1 | AD4: Dhaka Gladiators | AE4: =IF(Table5[[#This Row],[Team_Name]]=Table5[[#This Row],[Correct_Winner]],1,0) -> 1
A5: 2011/12 | B5: 2011 | C5: 2nd | D5: League | E5: Feb 28 2012 | F5: Dhaka Gladiators | G5: 191 | H5: 4 | I5: =Clean_Data!$I5 -> Duronto Rajshahi | J5: 182 | K5: 7 | L5: Azhar Mahmood | M5: Dhaka Gladiators | N5: bat first | O5: Dhaka | P5: Dhaka Gladiators | Q5: SBNCS | R5: Mirpur | S5: 0 | T5: 9 | U5: 9 runs | V5: Runs | W5: 9 | X5: Close Match | Y5: 373 | Z5: 170+ Match | AA5: Enamul Haque | AB5: Nadir Shah | AC5: team_2 | AD5: Khulna Royal Bengals | AE5: =IF(Table5[[#This Row],[Team_Name]]=Table5[[#This Row],[Correct_Winner]],1,0) -> 0
A6: 2011/12 | B6: 2011 | C6: 1st | D6: League | E6: Feb 28 2012 | F6: Chittagong Kings | G6: 184 | H6: 6 | I6: =Clean_Data!$I6 -> Barisal Burners | J6: 189 | K6: 2 | L6: Ahmed Shehzad | M6: Barisal Burners | N6: field first | O6: Barisal | P6: Barisal Burners | Q6: SBNCS | R6: Mirpur | S6: 8 | T6: 0 | U6: 8 wickets | V6: Wickets | W6: 8 | X6: Close Match | Y6: 373 | Z6: 170+ Match | AA6: David Orchard | AB6: Sharfuddoula | AC6: team_1 | AD6: Duronto Rajshahi | AE6: =IF(Table5[[#This Row],[Team_Name]]=Table5[[#This Row],[Correct_Winner]],1,0) -> 0
A7: 2011/12 | B7: 2011 | C7: 1st | D7: League | E7: Feb 28 2012 | F7: Khulna Royal Bengals | G7: 184 | H7: 6 | I7: =Clean_Data!$I7 -> Duronto Rajshahi | J7: 189 | K7: 2 | L7: Ahmed Shehzad | M7: Barisal Burners | N7: field first | O7: Barisal | P7: Barisal Burners | Q7: SBNCS | R7: Mirpur | S7: 8 | T7: 0 | U7: 8 wickets | V7: Wickets | W7: 8 | X7: Close Match | Y7: 373 | Z7: 170+ Match | AA7: David Orchard | AB7: Sharfuddoula | AC7: team_2 | AD7: Barisal Burners | AE7: =IF(Table5[[#This Row],[Team_Name]]=Table5[[#This Row],[Correct_Winner]],1,0) -> 1
A8: 2011/12 | B8: 2011 | C8: 29th | D8: League | E8: Feb 27 2012 | F8: Sylhet Royals | G8: 116 | H8: 10 | I8: =Clean_Data!$I8 -> Chittagong Kings | J8: 120 | K8: 7 | L8: Mohammad Sami | M8: Dhaka Gladiators | N8: bat first | O8: Rajshahi | P8: Duronto Rajshahi | Q8: SBNCS | R8: Mirpur | S8: 3 | T8: 0 | U8: 3 wickets | V8: Wickets | W8: 3 | X8: Close Match | Y8: 236 | Z8: 170+ Match | AA8: Mahfuzur Rahman | AB8: Nadir Shah | AC8: team_1 | AD8: Dhaka Gladiators | AE8: =IF(Table5[[#This Row],[Team_Name]]=Table5[[#This Row],[Correct_Winner]],1,0) -> 0
A9: 2011/12 | B9: 2011 | C9: 29th | D9: League | E9: Feb 27 2012 | F9: Barisal Burners | G9: 116 | H9: 10 | I9: =Clean_Data!$I9 -> Dhaka Gladiators | J9: 120 | K9: 7 | L9: Mohammad Sami | M9: Dhaka Gladiators | N9: bat first | O9: Rajshahi | P9: Duronto Rajshahi | Q9: SBNCS | R9: Mirpur | S9: 3 | T9: 0 | U9: 3 wickets | V9: Wickets | W9: 3 | X9: Close Match | Y9: 236 | Z9: 170+ Match | AA9: Mahfuzur Rahman | AB9: Nadir Shah | AC9: team_2 | AD9: Duronto Rajshahi | AE9: =IF(Table5[[#This Row],[Team_Name]]=Table5[[#This Row],[Correct_Winner]],1,0) -> 1
A10: 2011/12 | B10: 2011 | C10: 28th | D10: League | E10: Feb 26 2012 | F10: Duronto Rajshahi | G10: 150 | H10: 9 | I10: =Clean_Data!$I10 -> Sylhet Royals | J10: 151 | K10: 5 | L10: Brad Hodge | M10: Barisal Burners | N10: field first | O10: Barisal | P10: Barisal Burners | Q10: SBNCS | R10: Mirpur | S10: 5 | T10: 0 | U10: 5 wickets | V10: Wickets | W10: 5 | X10: Close Match | Y10: 301 | Z10: 170+ Match | AA10: Gazi Sohel | AB10: Jeremy Lloyds | AC10: team_1 | AD10: Chittagong Kings | AE10: =IF(Table5[[#This Row],[Team_Name]]=Table5[[#This Row],[Correct_Winner]],1,0) -> 0
A11: 2011/12 | B11: 2011 | C11: 28th | D11: League | E11: Feb 26 2012 | F11: Dhaka Gladiators | G11: 150 | H11: 9 | I11: =Clean_Data!$I11 -> Chittagong Kings | J11: 151 | K11: 5 | L11: Brad Hodge | M11: Barisal Burners | N11: field first | O11: Barisal | P11: Barisal Burners | Q11: SBNCS | R11: Mirpur | S11: 5 | T11: 0 | U11: 5 wickets | V11: Wickets | W11: 5 | X11: Close Match | Y11: 301 | Z11: 170+ Match | AA11: Gazi Sohel | AB11: Jeremy Lloyds | AC11: team_2 | AD11: Barisal Burners | AE11: =IF(Table5[[#This Row],[Team_Name]]=Table5[[#This Row],[Correct_Winner]],1,0) -> 1
A12: 2011/12 | B12: 2011 | C12: 27th | D12: League | E12: Feb 26 2012 | F12: Chittagong Kings | G12: 106 | H12: 10 | I12: =Clean_Data!$I12 -> Dhaka Gladiators | J12: 110 | K12: 2 | L12: Sean Ervine | M12: Khulna Royal Bengals | N12: bat first | O12: Rajshahi | P12: Duronto Rajshahi | Q12: SBNCS | R12: Mirpur | S12: 8 | T12: 0 | U12: 8 wickets | V12: Wickets | W12: 8 | X12: Close Match | Y12: 216 | Z12: 170+ Match | AA12: David Orchard | AB12: Nadir Shah | AC12: team_1 | AD12: Khulna Royal Bengals | AE12: =IF(Table5[[#This Row],[Team_Name]]=Table5[[#This Row],[Correct_Winner]],1,0) -> 0
A13: 2011/12 | B13: 2011 | C13: 27th | D13: League | E13: Feb 26 2012 | F13: Sylhet Royals | G13: 106 | H13: 10 | I13: =Clean_Data!$I13 -> Chittagong Kings | J13: 110 | K13: 2 | L13: Sean Ervine | M13: Khulna Royal Bengals | N13: bat first | O13: Rajshahi | P13: Duronto Rajshahi | Q13: SBNCS | R13: Mirpur | S13: 8 | T13: 0 | U13: 8 wickets | V13: Wickets | W13: 8 | X13: Close Match | Y13: 216 | Z13: 170+ Match | AA13: David Orchard | AB13: Nadir Shah | AC13: team_2 | AD13: Duronto Rajshahi | AE13: =IF(Table5[[#This Row],[Team_Name]]=Table5[[#This Row],[Correct_Winner]],1,0) -> 1
... A482: 2018/19 | B482: 2018 | C482: 25th | D482: League | E482: Jan 22 2019 | F482: Chittagong Kings | G482: 181 | H482: 6 | I482: =Clean_Data!$I482 -> Fortune Barishal | J482: 183 | K482: 4 | L482: Farhad Reza | M482: Rangpur Riders | N482: field first | O482: Riders | P482: Rangpur Riders | Q482: SBNCS | R482: Mirpur | S482: 6 | T482: 0 | U482: 6 wickets | V482: Wickets | W482: 6 | X482: Close Match | Y482: 364 | Z482: 170+ Match | AA482: Sharfuddoula | AB482: Shozab Raza | AC482: team_1 | AD482: Khulna Titans | AE482: =IF(Table5[[#This Row],[Team_Name]]=Table5[[#This Row],[Correct_Winner]],1,0) -> 0

Sheet Team_Analysis
A2: Correct_Winner | B2: Count of match_no | C2: Correct_Winner | D2: Count of match_no
A3: Barisal Bulls | B3: 11 | C3: Barisal Bulls | D3: 11
A4: Barisal Burners | B4: 11 | C4: Barisal Burners | D4: 11
A5: Chattogram Challengers | B5: 28 | C5: Chattogram Challengers | D5: 28
A6: Chittagong Kings | B6: 22 | C6: Chittagong Kings | D6: 22
A7: Chittagong Vikings | B7: 18 | C7: Chittagong Vikings | D7: 18
A8: Comilla Victorians | B8: 60 | C8: Comilla Victorians | D8: 60
A9: Comilla Victorians | B9: 5 | C9: Comilla Victorians | D9: 5
A10: Cumilla Warriors | B10: 4 | C10: Cumilla Warriors | D10: 4
A11: Dhaka Capital | B11: 3 | C11: Dhaka Capital | D11: 3
A12: Dhaka Dominators | B12: 3 | C12: Dhaka Dominators | D12: 3
A13: Dhaka Dynamites | B13: 30 | C13: Dhaka Dynamites | D13: 30
A14: Dhaka Gladiators | B14: 18 | C14: Dhaka Gladiators | D14: 18
... A34: Sylhet Thunder | B34: 2 | C34: Sylhet Thunder | D34: 2
A35: Grand Total | B35: 481
A43: Team_Name | B43: Count of Team_Name | C43: Sum of Win_Flag | D43: Team_Name | E43: Count of Team_Name | F43: Sum of Win_Flag | G43: Win %
A44: Barisal Bulls | B44: 24 | C44: 11 | D44: Fortune Barishal | E44: 45 | F44: 32 | G44: =C44/B44 -> 0.45833333
A45: Barisal Burners | B45: 24 | C45: 11 | D45: Dhaka Gladiators | E45: 26 | F45: 18 | G45: =C45/B45 -> 0.45833333
A46: Chattogram Challengers | B46: 59 | C46: 28 | D46: Comilla Victorians | E46: 89 | F46: 60 | G46: =C46/B46 -> 0.47457627
A47: Chittagong Kings | B47: 40 | C47: 22 | D47: Rajshahi Royals | E47: 15 | F47: 10 | G47: =C47/B47 -> 0.55
A48: Chittagong Vikings | B48: 47 | C48: 18 | D48: Fortune Barishal | E48: 14 | F48: 9 | G48: =C48/B48 -> 0.38297872
A49: Comilla Victorians | B49: 89 | C49: 60 | D49: Comilla Victorians | E49: 8 | F49: 5 | G49: =C49/B49 -> 0.6741573
A50: Comilla Victorians | B50: 8 | C50: 5 | D50: Rangpur Riders | E50: 93 | F50: 54 | G50: =C50/B50 -> 0.625
A51: Cumilla Warriors | B51: 12 | C51: 4 | D51: Dhaka Dynamites | E51: 52 | F51: 30 | G51: =C51/B51 -> 0.33333333
A52: Dhaka Capital | B52: 12 | C52: 3 | D52: Chittagong Kings | E52: 40 | F52: 22 | G52: =C52/B52 -> 0.25
A53: Dhaka Dominators | B53: 12 | C53: 3 | D53: Dhaka Platoon | E53: 13 | F53: 7 | G53: =C53/B53 -> 0.25
A54: Dhaka Dynamites | B54: 52 | C54: 30 | D54: Rangpur Rangers | E54: 26 | F54: 14 | G54: =C54/B54 -> 0.57692308
A55: Dhaka Gladiators | B55: 26 | C55: 18 | D55: Duronto Rajshahi | E55: 24 | F55: 12 | G55: =C55/B55 -> 0.69230769
... A75: Sylhet Thunder | B75: 12 | C75: 2 | D75: Durdanto Dhaka | E75: 12 | F75: 1 | G75: =C75/B75 -> 0.16666667
A76: Grand Total | B76: 962 | C76: 481
A84: Team_Name | B84: Average of team_1_score | C84: Average of team_2_score | D84: Count of match_no | E84: Team_Name | F84: Average of team_1_score | G84: Average of team_2_score | H84: Count of match_no | I84: Average Score Per Team
A85: Barisal Bulls | B85: 141 | C85: 131.58333 | D85: 24 | E85: Barisal Bulls | F85: 141 | G85: 132 | H85: 24 | I85: =(B85*(D85/2)+C85*(D85/2))/D85 -> 136.29167
A86: Barisal Burners | B86: 155.375 | C86: 151.16667 | D86: 24 | E86: Barisal Burners | F86: 155 | G86: 151 | H86: 24 | I86: =(B86*(D86/2)+C86*(D86/2))/D86 -> 153.27083
A87: Chattogram Challengers | B87: 160.15254 | C87: 150.32203 | D87: 59 | E87: Chattogram Challengers | F87: 160 | G87: 150 | H87: 59 | I87: =(B87*(D87/2)+C87*(D87/2))/D87 -> 155.23729
A88: Chittagong Kings | B88: 161.8 | C88: 136.875 | D88: 40 | E88: Chittagong Kings | F88: 162 | G88: 137 | H88: 40 | I88: =(B88*(D88/2)+C88*(D88/2))/D88 -> 149.3375
A89: Chittagong Vikings | B89: 154.85106 | C89: 145.17021 | D89: 47 | E89: Chittagong Vikings | F89: 155 | G89: 145 | H89: 47 | I89: =(B89*(D89/2)+C89*(D89/2))/D89 -> 150.01064
A90: Comilla Victorians | B90: 150.02247 | C90: 136.22472 | D90: 89 | E90: Comilla Victorians | F90: 150 | G90: 136 | H90: 89 | I90: =(B90*(D90/2)+C90*(D90/2))/D90 -> 143.1236
A91: Comilla Victorians | B91: 163.25 | C91: 143.375 | D91: 8 | E91: Comilla Victorians | F91: 163 | G91: 143 | H91: 8 | I91: =(B91*(D91/2)+C91*(D91/2))/D91 -> 153.3125
A92: Cumilla Warriors | B92: 177.41667 | C92: 154.41667 | D92: 12 | E92: Cumilla Warriors | F92: 177 | G92: 154 | H92: 12 | I92: =(B92*(D92/2)+C92*(D92/2))/D92 -> 165.91667
A93: Dhaka Capital | B93: 163.08333 | C93: 147.08333 | D93: 12 | E93: Dhaka Capital | F93: 163 | G93: 147 | H93: 12 | I93: =(B93*(D93/2)+C93*(D93/2))/D93 -> 155.08333
...

Sheet KPI_Analysis
A4: Total Matches | B4: =COUNTA(Table5[match_no]) -> 481
A8: Total Seasons | B8: =COUNTA(_xlfn.UNIQUE(Table5[season])) -> 8
A12: Highest Match Score | B12: =MAX(Table5[Total_Runs]) -> 422
A17: Best Win % Team | B17: =Team_Analysis!D44 -> Fortune Barishal
A21: Top Player Name | B21: =Team_Analysis!C128 -> Shakib hasan

Sheet Dashboard
